==================================== ERRORS ====================================
______________________ ERROR collecting tests/test_api.py ______________________
.pythonlibs/lib/python3.11/site-packages/_pytest/runner.py:341: in from_call
    result: Optional[TResult] = func()
.pythonlibs/lib/python3.11/site-packages/_pytest/runner.py:372: in <lambda>
    call = CallInfo.from_call(lambda: list(collector.collect()), "collect")
.pythonlibs/lib/python3.11/site-packages/_pytest/python.py:531: in collect
    self._inject_setup_module_fixture()
.pythonlibs/lib/python3.11/site-packages/_pytest/python.py:545: in _inject_setup_module_fixture
    self.obj, ("setUpModule", "setup_module")
.pythonlibs/lib/python3.11/site-packages/_pytest/python.py:310: in obj
    self._obj = obj = self._getobj()
.pythonlibs/lib/python3.11/site-packages/_pytest/python.py:528: in _getobj
    return self._importtestmodule()
.pythonlibs/lib/python3.11/site-packages/_pytest/python.py:617: in _importtestmodule
    mod = import_path(self.path, mode=importmode, root=self.config.rootpath)
.pythonlibs/lib/python3.11/site-packages/_pytest/pathlib.py:567: in import_path
    importlib.import_module(module_name)
/nix/store/clx0mcir7qw8zk36zbr4jra789g3knf6-python3-3.11.10/lib/python3.11/importlib/__init__.py:126: in import_module
    return _bootstrap._gcd_import(name[level:], package, level)
<frozen importlib._bootstrap>:1204: in _gcd_import
    ???
<frozen importlib._bootstrap>:1176: in _find_and_load
    ???
<frozen importlib._bootstrap>:1147: in _find_and_load_unlocked
    ???
<frozen importlib._bootstrap>:690: in _load_unlocked
    ???
.pythonlibs/lib/python3.11/site-packages/_pytest/assertion/rewrite.py:186: in exec_module
    exec(co, module.__dict__)
tests/test_api.py:17: in <module>
    client = TestClient(app)
.pythonlibs/lib/python3.11/site-packages/starlette/testclient.py:399: in __init__
    super().__init__(
E   TypeError: Client.__init__() got an unexpected keyword argument 'app'
=========================== short test summary info ============================
ERROR tests/test_api.py - TypeError: Client.__init__() got an unexpected keyw...
!!!!!!!!!!!!!!!!!!!! Interrupted: 1 error during collection !!!!!!!!!!!!!!!!!!!!
=============================== 1 error in 2.13s ===============================